<?xml version="1.0"?>

<robot
  xmlns:controller="http://playerstage.sourceforge.net/gazebo/xmlschema/#controller"
  xmlns:interface="http://ros.org/wiki/xacro"
  xmlns:sensor="http://playerstage.sourceforge.net/gazebo/xmlschema/#sensor"
  xmlns:xacro="http://ros.org/wiki/xacro">

  <xacro:include filename="$(find tuda_turtlebot3_arm_description)/urdf/tuda_turtlebot3_arm.gazebo.xacro" />

  <xacro:property name="XM430_W350_max_effort" value="4.1" />
  <xacro:property name="XM430_W350_max_velocity" value="${46 * 2*pi/60}" />

  <xacro:property name="joint_damping" value="0.2" />
  <xacro:property name="joint_friction" value="0.5" />

  <xacro:macro name="manipulator_arm_macro" params="parent *origin">
    <joint name="arm_base" type="fixed">
      <xacro:insert_block name="origin" />
      <parent link="${parent}" />
      <child link="arm_link_1" />
    </joint>

    <link name="arm_link_1">
      <visual>
        <origin xyz="0 0.0 0.0" rpy="0.0 0.0 ${pi}" />
        <geometry>
          <mesh filename="package://tuda_turtlebot3_arm_description/meshes/arm/link0.stl" scale="0.001 0.001 0.001" />
        </geometry>
        <material name="DarkGrey">
          <color rgba="0.3 0.3 0.3 1" />
        </material>
      </visual>

      <collision>
        <origin xyz="-0.011 0 0.018" rpy="0.0 0.0 ${pi}" />
        <geometry>
          <box size="0.05 0.03 0.035" />
        </geometry>
      </collision>

      <inertial>
        <origin xyz="-0.0129 0.00024 0.01759" rpy="0.0 0.0 ${pi}" />
        <mass value="0.082" />
        <inertia ixx="48.546e-06"   ixy="-0.218e-06"    ixz="-0.416e-06"
                                    iyy="25.118e-06"    iyz="17.510e-06"
                                                        izz="4.077e-06" />
      </inertial>
    </link>

    <joint name="arm_joint_1" type="revolute">
      <origin xyz="0.0 0 0.036" rpy="0.0 0.0 ${pi}" />
      <axis xyz="0.0 0.0 1" />
      <limit lower="${-pi+0.001}" upper="${pi-0.001}" effort="${XM430_W350_max_effort}" velocity="${XM430_W350_max_velocity}" />
      <parent link="arm_link_1" />
      <child link="arm_link_2" />
      <dynamics friction="${joint_friction}" damping="${joint_damping}" />
    </joint>

    <link name="arm_link_2">
      <visual>
        <origin xyz="0 0.0 0.0" rpy="0.0 0.0 0.0" />
        <geometry>
          <mesh filename="package://tuda_turtlebot3_arm_description/meshes/arm/link1.stl" scale="0.001 0.001 0.001" />
        </geometry>
        <material name="DarkGrey">
          <color rgba="0.3 0.3 0.3 1" />
        </material>
      </visual>

      <collision>
        <origin xyz="0.0 0 0.025" rpy="0.0 0.0 0.0" />
        <geometry>
          <box size="0.03 0.04 0.055" />
        </geometry>
      </collision>

      <inertial>
        <origin xyz="0.00023 -0.00056 0.026" rpy="0.0 0.0 0.0" />
        <mass value="0.088" />
        <inertia ixx="13.346e-06"   ixy="0.224e-06"     ixz="0.323e-06"
                                    iyy="7.757e-06"     iyz="0.438e-06"
                                                        izz="14.284e-06" />
      </inertial>
    </link>

    <joint name="arm_joint_2" type="revolute">
      <origin xyz="0.0 0.0 0.0405" rpy=" ${pi/2} 0.0 ${pi}" />
      <axis xyz="0.0 0.0 1" />
      <limit lower="${-100 * pi / 180}" upper="${100 * pi / 180}" effort="${XM430_W350_max_effort}" velocity="${XM430_W350_max_velocity}" />
      <parent link="arm_link_2" />
      <child link="arm_link_3" />
      <dynamics friction="${joint_friction}" damping="${joint_damping}" />
    </joint>

    <link name="arm_link_3">
      <visual>
        <origin xyz="0.0 0.0 0.0" rpy="0.0 0.0 0.0" />
        <geometry>
          <mesh filename="package://tuda_turtlebot3_arm_description/meshes/arm/link2.stl" scale="0.001 0.001 0.001" />
        </geometry>
        <material name="DarkGrey">
          <color rgba="0.3 0.3 0.3 1" />
        </material>
      </visual>

      <collision>
        <origin xyz="0 0.078 0.0" rpy="0.0 0.0 0.0" />
        <geometry>
          <box size="0.03 0.11 0.035" />
        </geometry>
      </collision>

      <collision>
        <origin xyz="0.012 0.145 0.0" rpy="0.0 0.0 0.0" />
        <geometry>
          <box size="0.05 0.035 0.04" />
        </geometry>
      </collision>

      <collision>
        <origin xyz="0.0 0.01 0.02" rpy="0.0 0.0 0.0" />
        <geometry>
          <box size="0.03 0.04 0.0075" />
        </geometry>
      </collision>

      <collision>
        <origin xyz="0.0 0.01 -0.02" rpy="0.0 0.0 0.0" />
        <geometry>
          <box size="0.03 0.04 0.0075" />
        </geometry>
      </collision>

      <inertial>
        <origin xyz="0.00746 0.12016 0.00036" rpy="0.0 ${pi} 0.0" />
        <mass value="0.136" />
        <inertia ixx="267.630e-06"    ixy="25.927e-06"    ixz="-0.339e-06"
                                      iyy="21.769e-06"    iyz="1.571e-06"
                                                          izz="260.554e-06" />
      </inertial>
    </link>

    <joint name="arm_joint_3" type="revolute">
      <origin xyz="0.024 0.148 0.0" rpy="0.0 0.0 ${-pi/2}" />
      <axis xyz="0.0 0.0 1" />
      <limit lower="${-180 * pi / 180}" upper="${25 * pi / 180}" effort="${XM430_W350_max_effort}" velocity="${XM430_W350_max_velocity}" />
      <parent link="arm_link_3" />
      <child link="arm_link_4" />
      <dynamics friction="${joint_friction}" damping="${joint_damping}" />
    </joint>

    <link name="arm_link_4">
      <visual>
        <origin xyz="0.0 0.0 0.0" rpy="0.0 0.0 0.0" />
        <geometry>
          <mesh filename="package://tuda_turtlebot3_arm_description/meshes/arm/link3.stl" scale="0.001 0.001 0.001" />
        </geometry>
        <material name="DarkGrey">
          <color rgba="0.3 0.3 0.3 1" />
        </material>
      </visual>

      <collision>
        <origin xyz="-0.01 0.0 0.02" rpy="0.0 0.0 0.0" />
        <geometry>
          <box size="0.04 0.03 0.0075" />
        </geometry>
      </collision>

      <collision>
        <origin xyz="-0.01 0.0 -0.02" rpy="0.0 0.0 0.0" />
        <geometry>
          <box size="0.04 0.03 0.0075" />
        </geometry>
      </collision>
      <collision>
        <origin xyz="-0.09 0.0 0.0" rpy="0.0 0.0 0.0" />
        <geometry>
          <box size="0.145 0.04 0.04" />
        </geometry>
      </collision>

      <inertial>
        <origin xyz="-0.11166 0.00016 0.00038" rpy="0.0 0.0 0.0" />
        <mass value="0.127" />
        <inertia ixx="19.832e-06"   ixy="-0.793e-06"      ixz="-0.724e-06"
                                    iyy="215.338e-06"     iyz="-0.221e-06"
                                                          izz="207.743e-06" />
      </inertial>
    </link>

    <joint name="arm_joint_4" type="revolute">
      <origin xyz="-0.15 0.0 0.0" rpy="0.0 0.0 0.0" />
      <axis xyz="0.0 0.0 1" />
      <limit lower="${-95 * pi / 180}" upper="${95 * pi / 180}" effort="${XM430_W350_max_effort}" velocity="${XM430_W350_max_velocity}" />
      <parent link="arm_link_4" />
      <child link="gripper_base_link" />
      <dynamics friction="${joint_friction}" damping="${joint_damping}" />
    </joint>

    <link name="gripper_base_link">
      <visual>
        <origin xyz="0.0 0.0 0.0" rpy="0.0 0.0 0.0" />
        <geometry>
          <mesh filename="package://tuda_turtlebot3_arm_description/meshes/gripper/gripper_base.stl" scale="0.001 0.001 0.001" />
        </geometry>
        <material name="DarkGrey">
          <color rgba="0.3 0.3 0.3 1" />
        </material>
      </visual>

      <collision>
        <origin xyz="-0.01 0.0 0.02" rpy="0.0 0.0 0.0" />
        <geometry>
          <box size="0.04 0.03 0.0075" />
        </geometry>
      </collision>

      <collision>
        <origin xyz="-0.01 0.0 -0.02" rpy="0.0 0.0 0.0" />
        <geometry>
          <box size="0.04 0.03 0.0075" />
        </geometry>
      </collision>

      <collision>
        <origin xyz="-0.05 0.0 0.0" rpy="0.0 0.0 0.0" />
        <geometry>
          <box size="0.05 0.05 0.055" />
        </geometry>
      </collision>

      <collision>
        <origin xyz="-0.06 0.0325 0.0" rpy="0.0 0.0 0.0" />
        <geometry>
          <box size="0.0685 0.015 0.055" />
        </geometry>
      </collision>

      <collision>
        <origin xyz="-0.06 -0.0325 0.0" rpy="0.0 0.0 0.0" />
        <geometry>
          <box size="0.0685 0.015 0.055" />
        </geometry>
      </collision>

      <collision>
        <origin xyz="-0.06908 0.035 0.02" rpy="${pi/2} ${pi} 0.0" />
        <geometry>
          <cylinder length="0.01" radius="0.026" />
        </geometry>
      </collision>

      <collision>
        <origin xyz="-0.06908 -0.035 0.02" rpy="${pi/2} ${pi} 0.0" />
        <geometry>
          <cylinder length="0.01" radius="0.026" />
        </geometry>
      </collision>

      <collision>
        <origin xyz="-0.06908 0.035 -0.02" rpy="${-pi/2} ${pi} 0.0" />
        <geometry>
          <cylinder length="0.01" radius="0.026" />
        </geometry>
      </collision>

      <collision>
        <origin xyz="-0.06908 -0.035 -0.02" rpy="${-pi/2} ${pi} 0.0" />
        <geometry>
          <cylinder length="0.01" radius="0.026" />
        </geometry>
      </collision>

	  <collision>
        <origin xyz="-0.05408 0.0405 -0.01912" rpy="${pi/2} ${pi} 0.0" />
        <geometry>
          <cylinder length="0.007" radius="0.00205" />
        </geometry>
      </collision>

	  <collision>
        <origin xyz="-0.05408 0.0405 0.01887" rpy="${pi/2} ${pi} 0.0" />
        <geometry>
          <cylinder length="0.007" radius="0.00205" />
        </geometry>
      </collision>

      <inertial>

        <origin xyz="-0.04663 -0.00051 -0.00234" rpy="0.0 0.0 0.0" />
        <mass value="0.155" />
        <inertia ixx="114.015e-06"    ixy="17.253e-06"    ixz="-1.650e-06"
                                      iyy="70.718e-06"    iyz="0.750e-06"
                                                          izz="141.557e-06" />
      </inertial>
    </link>

    <joint name="gripper_servo_joint" type="revolute">
      <origin xyz="-0.04225 0.0 -0.016" rpy="${pi/2} 0 0.0" />
      <axis xyz="0.0 0.0 1" />
      <limit lower="-1.93" upper="1.62" effort="${XM430_W350_max_effort}" velocity="${XM430_W350_max_velocity}" />
      <parent link="gripper_base_link" />
      <child link="gripper_servo_link" />
      <dynamics friction="0" damping="0" />
    </joint>

    <link name="gripper_servo_link">
      <inertial>
        <origin xyz="0.0 0.0 0.0" rpy="0.0 0.0 0.0" />
        <mass value="0.001" />
        <inertia ixx="1.0e-07" ixy="0.0"     ixz="0.0"
                              iyy="1.0e-07"  iyz="0.0"
                                            izz="1.0e-07" />
      </inertial>

      <collision>
        <origin xyz="0 0.0 0.0275" rpy="0.0 0.0 0.0" />
        <geometry>
          <cylinder length="0.01" radius="0.01" />
        </geometry>
      </collision>
    </link>

    <!-- virtual endeffector joint -->
    <joint name="gripper_grasp" type="fixed">
      <origin xyz="-0.14 0.0 0.0" rpy="0.0 0.0 ${pi}"/>
      <parent link="gripper_base_link"/>
      <child link="gripper_grasp_link"/>
    </joint>

    <link name="gripper_grasp_link">
    <visual>
      <origin xyz="0.0 0.0 0.0" rpy="0.0 0.0 0.0"/>
      <geometry>
        <sphere radius="0.005" />
      </geometry>
      <material name="Red">
        <color rgba="1.0 0.0 0.0 1" />
      </material>
    </visual>

    <inertial>
      <origin xyz="0.0 0.0 0.0" rpy="0.0 0.0 0.0"/>
      <mass value="0.0001"/>
    <inertia ixx="1.0e-10" ixy="0.0" ixz="0.0" iyy="1.0e-10" iyz="0.0" izz="1.0e-10" />
    </inertial>
    </link>

	  <!-- gripper finger -->
    <joint name="gripper_finger_joint_1" type="continuous">
      <origin xyz="-0.06908 0.0 0.02" rpy="${pi/2} ${pi-pi/5} 0.0" />
      <axis xyz="0.0 0.0 1" />
      <limit lower="${-pi}" upper="${pi}" effort="${XM430_W350_max_effort}" velocity="${XM430_W350_max_velocity}" />
      <parent link="gripper_base_link" />
      <child link="gripper_finger_link_1" />
      <mimic joint="gripper_servo_joint" multiplier="${8 / 23}" offset="0" />
      <dynamics friction="${joint_friction}" damping="${joint_damping}" />
    </joint>

    <link name="gripper_finger_link_1">
      <visual>
        <origin xyz="0.0 0.0 0.0" rpy="0.0 0.0 0.0" />
        <geometry>
          <mesh filename="package://tuda_turtlebot3_arm_description/meshes/gripper/gripper_finger.stl" scale="-0.001 0.001 0.001" />
        </geometry>
        <material name="DarkGrey">
          <color rgba="0.3 0.3 0.3 1" />
        </material>
      </visual>

      <collision>
        <origin xyz="0 0.0 0.025" rpy="0.0 0.0 0.0" />
        <geometry>
          <cylinder length="0.01" radius="0.023" />
        </geometry>
      </collision>

      <collision>
        <origin xyz="0 0.0 -0.025" rpy="0.0 0.0 0.0" />
        <geometry>
          <cylinder length="0.01" radius="0.023" />
        </geometry>
      </collision>

      <collision>
        <origin xyz="0.045 -0.055 0.0" rpy="0.0 0.0 ${-58 * pi / 180}" />
        <geometry>
          <box size="0.095 0.005 0.03" />
        </geometry>
      </collision>

      <collision>
        <origin xyz="0.0275 -0.0725 0.0" rpy="0.0 0.0 ${-31 * pi / 180}" />
        <geometry>
          <box size="0.095 0.005 0.03" />
        </geometry>
      </collision>

      <collision>
        <origin xyz="0.005 -0.035 0.0" rpy="0.0 0.0 ${45 * pi / 180}" />
        <geometry>
          <box size="0.05 0.005 0.03" />
        </geometry>
      </collision>

      <collision>
        <origin xyz="0.0 -0.025 0.0" rpy="0.0 0.0 ${45 * pi / 180}" />
        <geometry>
          <box size="0.03 0.03 0.06" />
        </geometry>
      </collision>

      <inertial>
        <origin xyz="0.01764 -0.04373 0.0" rpy="0.0 0.0 ${90 * pi / 180}" />
        <mass value="0.029" />
        <inertia ixx="0.000025065339"   ixy="-0.000009627959" ixz="2.8255e-8"
                                        iyy="0.000022245643"  iyz="5.37e-10"
                                                              izz="0.000027220956" />
      </inertial>
    </link>

    <joint name="gripper_finger_joint_2" type="continuous">
      <origin xyz="-0.06908 0.0 -0.02" rpy="${-pi/2} ${pi+pi/5} 0.0" />
      <axis xyz="0.0 0.0 1" />
      <limit lower="${-pi}" upper="${pi}" effort="${XM430_W350_max_effort}" velocity="${XM430_W350_max_velocity}" />
      <parent link="gripper_base_link" />
      <child link="gripper_finger_link_2" />
      <mimic joint="gripper_servo_joint" multiplier="${8 / 23}" offset="0" />
      <dynamics friction="${joint_friction}" damping="${joint_damping}" />
    </joint>

    <link name="gripper_finger_link_2">
      <visual>
        <origin xyz="0.0 0.0 0.0" rpy="0.0 0.0 0.0" />
        <geometry>
          <mesh filename="package://tuda_turtlebot3_arm_description/meshes/gripper/gripper_finger.stl" scale="-0.001 0.001 0.001" />
        </geometry>
        <material name="DarkGrey">
          <color rgba="0.3 0.3 0.3 1" />
        </material>
      </visual>

      <collision>
        <origin xyz="0 0.0 0.025" rpy="0.0 0.0 0.0" />
        <geometry>
          <cylinder length="0.01" radius="0.023" />
        </geometry>
      </collision>

      <collision>
        <origin xyz="0 0.0 -0.025" rpy="0.0 0.0 0.0" />
        <geometry>
          <cylinder length="0.01" radius="0.023" />
        </geometry>
      </collision>

      <collision>
        <origin xyz="0.045 -0.055 0.0" rpy="0.0 0.0 ${- 58 * pi / 180}" />
        <geometry>
          <box size="0.095 0.005 0.03" />
        </geometry>
      </collision>

      <collision>
        <origin xyz="0.0275 -0.0725 0.0" rpy="0.0 0.0 ${-31 * pi / 180}" />
        <geometry>
          <box size="0.095 0.005 0.03" />
        </geometry>
      </collision>

      <collision>
        <origin xyz="0.005 -0.035 0.0" rpy="0.0 0.0 ${45 * pi / 180}" />
        <geometry>
          <box size="0.05 0.005 0.03" />
        </geometry>
      </collision>

      <collision>
        <origin xyz="0.0 -0.025 0.0" rpy="0.0 0.0 ${45 * pi / 180}" />
        <geometry>
          <box size="0.03 0.03 0.06" />
        </geometry>
      </collision>

      <inertial>
        <origin xyz="0.01764 -0.04373 0.0" rpy="0.0 0.0 ${90 * pi / 180}" />
        <mass value="0.029" />
        <inertia ixx="0.000025065339" ixy="-0.000009627959" ixz="2.8255e-8"
                                      iyy="0.000022245643"  iyz="5.37e-10"
                                                            izz="0.000027220956" />
      </inertial>
    </link>
  </xacro:macro>
</robot>
