<?xml version="1.0" ?>
<!-- =================================================================================== -->
<!-- |    This document was autogenerated by xacro from tuda_turtlebot3.xacro          | -->
<!-- |    EDITING THIS FILE BY HAND IS NOT RECOMMENDED                                 | -->
<!-- =================================================================================== -->
<robot name="turtlebot3" xmlns:controller="http://playerstage.sourceforge.net/gazebo/xmlschema/#controller" xmlns:interface="http://ros.org/wiki/xacro" xmlns:sensor="http://playerstage.sourceforge.net/gazebo/xmlschema/#sensor" xmlns:xacro="http://ros.org/wiki/xacro">
  <!-- Init colour -->
  <material name="black">
    <color rgba="0.0 0.0 0.0 1.0"/>
  </material>
  <material name="dark">
    <color rgba="0.3 0.3 0.3 1.0"/>
  </material>
  <material name="light_black">
    <color rgba="0.4 0.4 0.4 1.0"/>
  </material>
  <material name="blue">
    <color rgba="0.0 0.0 0.8 1.0"/>
  </material>
  <material name="green">
    <color rgba="0.0 0.8 0.0 1.0"/>
  </material>
  <material name="grey">
    <color rgba="0.2 0.2 0.2 1.0"/>
  </material>
  <material name="orange">
    <color rgba="1.0 0.423529411765 0.0392156862745 1.0"/>
  </material>
  <material name="brown">
    <color rgba="0.870588235294 0.811764705882 0.764705882353 1.0"/>
  </material>
  <material name="red">
    <color rgba="0.8 0.0 0.0 1.0"/>
  </material>
  <material name="white">
    <color rgba="1.0 1.0 1.0 1.0"/>
  </material>
  <gazebo>
    <plugin filename="libgazebo_ros_control.so" name="gazebo_ros_control">
      <robotNamespace>/gazebo/turtlebot3/joints</robotNamespace>
      <robotParam>/turtlebot3/robot_description</robotParam>
      <robotSimType>gazebo_ros_control/DefaultRobotHWSim</robotSimType>
      <legacyModeNS>true</legacyModeNS>
    </plugin>
  </gazebo>
  <transmission name="wheel_left_joint_transmission">
    <type>transmission_interface/SimpleTransmission</type>
    <joint name="wheel_left_joint">
      <hardwareInterface>hardware_interface/EffortJointInterface</hardwareInterface>
    </joint>
    <actuator name="wheel_left_joint_motor">
      <hardwareInterface>hardware_interface/EffortJointInterface</hardwareInterface>
      <mechanicalReduction>1</mechanicalReduction>
    </actuator>
  </transmission>
  <transmission name="wheel_right_joint_transmission">
    <type>transmission_interface/SimpleTransmission</type>
    <joint name="wheel_right_joint">
      <hardwareInterface>hardware_interface/EffortJointInterface</hardwareInterface>
    </joint>
    <actuator name="wheel_right_joint_motor">
      <hardwareInterface>hardware_interface/EffortJointInterface</hardwareInterface>
      <mechanicalReduction>1</mechanicalReduction>
    </actuator>
  </transmission>
  <gazebo reference="base_link">
    <material>Gazebo/DarkGrey</material>
  </gazebo>
  <gazebo reference="usb_mount_link">
    <material>Gazebo/DarkGrey</material>
  </gazebo>
  <gazebo reference="camera_mount_link">
    <material>Gazebo/DarkGrey</material>
  </gazebo>
  <gazebo reference="wheel_left_link">
    <mu1>100.0</mu1>
    <mu2>100.0</mu2>
    <kp>1000000.0</kp>
    <kd>10.0</kd>
    <minDepth>0.001</minDepth>
    <maxVel>0.1</maxVel>
    <material>Gazebo/DarkGrey</material>
  </gazebo>
  <gazebo reference="wheel_right_link">
    <mu1>100.0</mu1>
    <mu2>100.0</mu2>
    <kp>1000000.0</kp>
    <kd>10.0</kd>
    <minDepth>0.001</minDepth>
    <maxVel>0.1</maxVel>
    <material>Gazebo/DarkGrey</material>
  </gazebo>
  <gazebo reference="caster_front_left_link">
    <mu1>0.0</mu1>
    <mu2>0.0</mu2>
    <kp>1000000.0</kp>
    <kd>10.0</kd>
    <minDepth>0.001</minDepth>
    <maxVel>1.0</maxVel>
    <material>Gazebo/Grey</material>
  </gazebo>
  <gazebo reference="caster_front_right_link">
    <mu1>0.0</mu1>
    <mu2>0.0</mu2>
    <kp>1000000.0</kp>
    <kd>10.0</kd>
    <minDepth>0.001</minDepth>
    <maxVel>1.0</maxVel>
    <material>Gazebo/Grey</material>
  </gazebo>
  <gazebo reference="imu_link">
    <sensor name="imu" type="imu">
      <imu/>
      <plugin filename="libgazebo_ros_imu_sensor.so" name="imu_plugin">
        <robotNamespace/>
        <frameName>imu_link</frameName>
        <topicName>/turtlebot3/sensor/imu_raw</topicName>
        <updateRateHZ>100.0</updateRateHZ>
        <gaussianNoise>0.001</gaussianNoise>
        <xyzOffset>0.0 0.0 0.0</xyzOffset>
        <rpyOffset>0.0 0.0 0.0</rpyOffset>
      </plugin>
    </sensor>
  </gazebo>
  <gazebo reference="base_scan">
    <material>Gazebo/DarkGrey</material>
    <sensor name="lds_lfcd_sensor" type="ray">
      <pose>0 0 0 0 0 0</pose>
      <visualize>False</visualize>
      <update_rate>5</update_rate>
      <ray>
        <scan>
          <horizontal>
            <samples>360</samples>
            <resolution>1</resolution>
            <min_angle>0.0</min_angle>
            <max_angle>6.28</max_angle>
          </horizontal>
        </scan>
        <range>
          <min>0.120</min>
          <max>3.5</max>
          <resolution>0.015</resolution>
        </range>
        <noise>
          <type>gaussian</type>
          <mean>0.0</mean>
          <stddev>0.01</stddev>
        </noise>
      </ray>
      <plugin filename="libgazebo_ros_laser.so" name="gazebo_ros_lds_lfcd_controller">
        <robotNamespace>/turtlebot3/sensor</robotNamespace>
        <topicName>scan_raw</topicName>
        <frameName>base_scan</frameName>
      </plugin>
    </sensor>
  </gazebo>
  <link name="base_footprint"/>
  <joint name="base_joint" type="fixed">
    <parent link="base_footprint"/>
    <child link="base_link"/>
    <origin rpy="0.0 0.0 0.0" xyz="0.0 0.0 0.0"/>
  </joint>
  <link name="base_link">
    <visual>
      <origin rpy="0.0 0.0 3.14159265359" xyz="0.032 0.0 0.0"/>
      <geometry>
        <mesh filename="package://tuda_turtlebot3_description/meshes/base/tuda_turtlebot3_base.stl" scale="0.001 0.001 0.001"/>
      </geometry>
      <material name="light_black"/>
    </visual>
    <collision>
      <origin rpy="0.0 0.0 3.14159265359" xyz="0.032 0.0 0.0465"/>
      <geometry>
        <box size="0.13755 0.140 0.093"/>
      </geometry>
    </collision>
    <collision>
      <origin rpy="0.0 0.0 3.14159265359" xyz="0.032 0.0 0.119"/>
      <geometry>
        <box size="0.13755 0.092 0.052"/>
      </geometry>
    </collision>
    <collision>
      <origin rpy="0.0 0.0 3.14159265359" xyz="0.133 0.0 0.025"/>
      <geometry>
        <box size="0.068 0.140 0.05"/>
      </geometry>
    </collision>
    <collision>
      <origin rpy="0.0 0.0 0.0" xyz="0.17407 0.0 0.013"/>
      <geometry>
        <box size="0.0145 0.140 0.026"/>
      </geometry>
    </collision>
    <inertial>
      <origin rpy="0.0 0.0 3.14159265359" xyz="0.0 0.00062 0.01577"/>
      <mass value="1.265"/>
      <inertia ixx="3316.323e-06" ixy="-116.278e-06" ixz="406.012e-06" iyy="4901.926e-06" iyz="28.730e-06" izz="4991.998e-06"/>
    </inertial>
  </link>
  <joint name="wheel_left_joint" type="continuous">
    <parent link="base_link"/>
    <child link="wheel_left_link"/>
    <origin rpy="1.57079632679 0 3.14159265359" xyz="0.0 0.08 0.02325"/>
    <axis xyz="0 0 1"/>
    <limit effort="1.5" velocity="6.3879050623"/>
    <joint_properties damping="0.5" friction="{wheel_joint_friction}"/>
  </joint>
  <link name="wheel_left_link">
    <visual>
      <origin rpy="0 0 0" xyz="0.0 0.0 0.0"/>
      <geometry>
        <mesh filename="package://tuda_turtlebot3_description/meshes/wheels/tire_on_wheel.stl" scale="0.001 0.001 0.001"/>
      </geometry>
      <material name="dark"/>
    </visual>
    <collision>
      <origin rpy="0.0 0.0 0.0" xyz="0.0 0.0 0.0"/>
      <geometry>
        <cylinder length="0.018" radius="0.033"/>
      </geometry>
    </collision>
    <inertial>
      <origin xyz="0.0 0.0 0.0"/>
      <mass value="0.061"/>
      <inertia ixx="21.298e-06" ixy="-0.007e-06" ixz="-0.003e-06" iyy="21.289e-06" iyz="0.006e-06" izz="39.702e-06"/>
    </inertial>
  </link>
  <joint name="wheel_right_joint" type="continuous">
    <parent link="base_link"/>
    <child link="wheel_right_link"/>
    <origin rpy="1.57079632679 0 3.14159265359" xyz="0.0 -0.08 0.02325"/>
    <axis xyz="0 0 1"/>
    <limit effort="1.5" velocity="6.3879050623"/>
    <joint_properties damping="0.5" friction="{wheel_joint_friction}"/>
  </joint>
  <link name="wheel_right_link">
    <visual>
      <origin rpy="0 0 0" xyz="0.0 0.0 0.0"/>
      <geometry>
        <mesh filename="package://tuda_turtlebot3_description/meshes/wheels/tire_on_wheel.stl" scale="0.001 0.001 -0.001"/>
      </geometry>
      <material name="dark"/>
    </visual>
    <collision>
      <origin rpy="0.0 0.0 0.0" xyz="0.0 0.0 0.0"/>
      <geometry>
        <cylinder length="0.018" radius="0.033"/>
      </geometry>
    </collision>
    <inertial>
      <origin xyz="0.0 0.0 0.0"/>
      <mass value="0.061"/>
      <inertia ixx="21.302e-06" ixy="0.002e-06" ixz="0.0" iyy="21.286e-06" iyz="0.006e-06" izz="39.702e-06"/>
    </inertial>
  </link>
  <joint name="caster_front_left_joint" type="fixed">
    <parent link="base_link"/>
    <child link="caster_front_left_link"/>
    <origin rpy="0.0 0.0 0.0" xyz="0.144 0.052 -0.006"/>
  </joint>
  <link name="caster_front_left_link">
    <visual>
      <origin rpy="0.0 0.0 0.0" xyz="0.0 0.0 0.0065"/>
      <geometry>
        <mesh filename="package://tuda_turtlebot3_description/meshes/base/ball_caster.stl" scale="0.001 0.001 0.001"/>
      </geometry>
      <material name="light_black"/>
    </visual>
    <collision>
      <origin rpy="0.0 0.0 0.0" xyz="0.0 0.0 0.0"/>
      <geometry>
        <sphere radius="0.004"/>
      </geometry>
    </collision>
    <inertial>
      <origin xyz="0.001 0 0.00073"/>
      <mass value="0.004"/>
      <inertia ixx="0.115e-06" ixy="0.0" ixz="0.0" iyy="0.274e-06" iyz="0.0" izz="0.206e-06"/>
    </inertial>
  </link>
  <joint name="caster_front_right_joint" type="fixed">
    <parent link="base_link"/>
    <child link="caster_front_right_link"/>
    <origin rpy="0.0 0.0 0.0" xyz="0.144 -0.052 -0.006"/>
  </joint>
  <link name="caster_front_right_link">
    <visual>
      <origin rpy="0.0 0.0 0.0" xyz="0.0 0.0 0.0065"/>
      <geometry>
        <mesh filename="package://tuda_turtlebot3_description/meshes/base/ball_caster.stl" scale="0.001 0.001 0.001"/>
      </geometry>
      <material name="light_black"/>
    </visual>
    <collision>
      <origin rpy="0.0 0.0 0.0" xyz="0.0 0.0 0.0"/>
      <geometry>
        <sphere radius="0.004"/>
      </geometry>
    </collision>
    <inertial>
      <origin xyz="0.001 0 0.00073"/>
      <mass value="0.004"/>
      <inertia ixx="0.115e-06" ixy="0.0" ixz="0.0" iyy="0.274e-06" iyz="0.0" izz="0.206e-06"/>
    </inertial>
  </link>
  <joint name="usb_mount_joint" type="fixed">
    <parent link="base_link"/>
    <child link="usb_mount_link"/>
    <origin rpy="0.0 0.0 3.14159265359" xyz="0.127 0.024 0.04875"/>
  </joint>
  <link name="usb_mount_link">
    <visual>
      <origin rpy="0.0 0.0 0.0" xyz="0.0 0.0 0.0"/>
      <geometry>
        <mesh filename="package://tuda_turtlebot3_description/meshes/base/usb_mount.stl" scale="0.001 0.001 0.001"/>
      </geometry>
      <material name="light_black"/>
    </visual>
    <collision>
      <origin rpy="0.0 0.0 0.0" xyz="0.031 -0.020 -0.006"/>
      <geometry>
        <box size="0.062 0.040 0.012"/>
      </geometry>
    </collision>
    <collision>
      <origin rpy="0.0 0.0 0.0" xyz="0.031 -0.02904 0.025"/>
      <geometry>
        <box size="0.021 0.015 0.050"/>
      </geometry>
    </collision>
    <collision>
      <origin rpy="0.0 0.0 0.0" xyz="0.031 -0.02904 -0.011"/>
      <geometry>
        <box size="0.021 0.01921 0.022"/>
      </geometry>
    </collision>
    <inertial>
      <origin xyz="0.001 0 0.00073"/>
      <mass value="0.005"/>
      <inertia ixx="0.1e-06" ixy="0.0" ixz="0.0" iyy="0.1e-06" iyz="0.0" izz="0.1e-06"/>
    </inertial>
  </link>
  <!-- TurtleBot3 Sensors-->
  <joint name="imu_joint" type="fixed">
    <parent link="base_link"/>
    <child link="imu_link"/>
    <origin rpy="0.0 0.0 0.0" xyz="0.0265 0.007 0.058"/>
  </joint>
  <link name="imu_link">
    <inertial>
      <origin xyz="0.0 0.0 0.0"/>
      <mass value="0.01"/>
      <inertia ixx="0.001" ixy="0.0" ixz="0.0" iyy="0.001" iyz="0.0" izz="0.001"/>
    </inertial>
  </link>
  <joint name="scan_joint" type="fixed">
    <parent link="base_link"/>
    <child link="base_scan"/>
    <origin rpy="0.0 0.0 0.0" xyz="0.02076 0 0.1225"/>
  </joint>
  <link name="base_scan">
    <visual>
      <origin rpy="0.0 0.0 3.14159265359" xyz="0.0 0.0 -0.01"/>
      <geometry>
        <mesh filename="package://tuda_turtlebot3_description/meshes/sensors/lds.stl" scale="0.001 0.001 0.001"/>
      </geometry>
      <material name="dark"/>
    </visual>
    <collision>
      <origin rpy="0.0 0.0 0.0" xyz="0.012 0.0 -0.01"/>
      <geometry>
        <cylinder length="0.040" radius="0.05"/>
      </geometry>
    </collision>
    <inertial>
      <mass value="0.125"/>
      <origin xyz="-0.00687 0.0001 0.0038"/>
      <inertia ixx="-1.801e-06" ixy="-0.007e-06" ixz="3.231e-06" iyy="-7.595e-06" iyz="0.004e-06" izz="-5.794e-06"/>
    </inertial>
  </link>
  <joint name="realsense_mount_joint" type="fixed">
    <parent link="base_link"/>
    <child link="camera_mount_link"/>
    <origin rpy="0.0 0.0 3.14159265359" xyz="0.17407 -0.04586 0.03995"/>
  </joint>
  <link name="camera_mount_link">
    <visual>
      <origin rpy="0.0 0.0 0.0" xyz="0.00133 -0.046 -0.00326"/>
      <geometry>
        <mesh filename="package://tuda_turtlebot3_description/meshes/base/realsense_mount.stl" scale="0.001 0.001 0.001"/>
      </geometry>
      <material name="dark"/>
    </visual>
    <collision>
      <origin rpy="0.0 0.0 0.0" xyz="0.00133 -0.056 -0.00326"/>
      <geometry>
        <box size="0.0175 0.154 0.024"/>
      </geometry>
    </collision>
    <inertial>
      <mass value="0.023"/>
      <origin xyz="0.00616 -0.04132 -0.00000235"/>
      <inertia ixx="40.506e-06" ixy="-0.712e-06" ixz="0.472e-06" iyy="2.546e-06" iyz="-0.601e-06" izz="39.799e-06"/>
    </inertial>
  </link>
  <joint name="camera_joint" type="fixed">
    <origin rpy="0.0 0.0 3.14159265359" xyz="0.0 0.005 -0.00337"/>
    <parent link="camera_mount_link"/>
    <child link="camera_link"/>
  </joint>
  <link name="camera_link">
    <inertial>
      <mass value="0.200"/>
      <origin rpy="0 0 0" xyz="0 0 0"/>
      <inertia ixx="5.8083e-4" ixy="0" ixz="0" iyy="3.0833e-5" iyz="0" izz="5.9083e-4"/>
    </inertial>
    <visual>
      <origin rpy="0 0 0" xyz="0 0.051 0"/>
      <geometry>
        <!--Dimensions taken from https://software.intel.com/en-us/realsense/devkit-->
        <box size="0.007 0.130 0.02"/>
      </geometry>
      <material name="DarkGrey">
        <color rgba="0.3 0.3 0.3 1"/>
      </material>
    </visual>
    <!--        
       <collision>
          <origin xyz="0 0 0" rpy="0 0 0" />
          <geometry>
            <box size="0.035 0.185 0.025"/>
          </geometry>
        </collision>
        -->
    <collision>
      <origin rpy="0 0 0" xyz="0 0.051 0"/>
      <geometry>
        <!--Dimensions taken from https://software.intel.com/en-us/realsense/devkit-->
        <box size="0.007 0.130 0.02"/>
      </geometry>
    </collision>
  </link>
  <!--      <joint name="${name}_depth_joint" type="fixed">
        <origin xyz="0 -0.051 0.004" rpy="0 0 0" />
        <parent link="${name}_link" />
        <child link="${name}_depth_frame"/>
      </joint>

      <link name="${name}_depth_frame"/>

      <joint name="${name}_depth_optical_joint" type="fixed">
        <origin xyz="0 0 0" rpy="${-pi/2} 0.0 ${-pi/2}" />
        <parent link="${name}_depth_frame" />
        <child link="${name}_depth_optical_frame"/>
      </joint>

      <link name="${name}_depth_optical_frame"/>


      <joint name="${name}_depth_joint_aux" type="fixed">
        <origin xyz="0 0.032 0.004" rpy="0 0 0" />
        <parent link="${name}_link" />
        <child link="${name}_depth_frame_aux"/>
      </joint>

      <link name="${name}_depth_frame_aux"/>

      <joint name="${name}_depth_optical_joint_aux" type="fixed">
        <origin xyz="0 0 0" rpy="${-pi/2} 0.0 ${-pi/2}" />
        <parent link="${name}_depth_frame_aux" />
        <child link="${name}_depth_optical_frame_aux"/>
      </joint>

      <link name="${name}_depth_optical_frame_aux"/>


      <joint name="${name}_rgb_joint" type="fixed">
        <origin xyz="0 -0.045 0.004" rpy="0 0 0" />
        <parent link="${name}_link" />
        <child link="${name}_rgb_frame"/>
      </joint>

      <link name="${name}_rgbd_cam_link"/>

      <joint name="${name}_rgb_optical_joint" type="fixed">
        <origin xyz="0 0 0" rpy="${-pi/2} 0.0 ${-pi/2}" />
        <parent link="${name}_rgb_frame" />
        <child link="${name}_rgb_optical_frame"/>
      </joint>

      <link name="${name}_rgb_optical_frame"/>-->
  <gazebo reference="camera_link">
    <material>Gazebo/Blue</material>
  </gazebo>
  <gazebo reference="camera_link">
    <sensor name="camera_rgb" type="camera">
      <always_on>1</always_on>
      <update_rate>30</update_rate>
      <camera>
        <horizontal_fov>1.2217304764</horizontal_fov>
        <image>
          <format>B8G8R8</format>
          <width>1920</width>
          <height>1080</height>
        </image>
        <clip>
          <near>0.001</near>
          <far>100</far>
        </clip>
        <distortion>
          <k1>0.0</k1>
          <k2>0.0</k2>
          <k3>0.0</k3>
          <p1>-0.0</p1>
          <p2>-0.00</p2>
          <center>0.5 0.5</center>
        </distortion>
      </camera>
      <plugin filename="libgazebo_ros_camera.so" name="camera_camera_depth_controller">
        <robotNamespace>turtlebot3/sensor/camera/rgb</robotNamespace>
        <imageTopicName>image_raw</imageTopicName>
        <cameraInfoTopicName>camera_info</cameraInfoTopicName>
        <frameName>camera_rgb_optical_frame</frameName>
      </plugin>
    </sensor>
    <sensor name="camera_depth" type="depth">
      <update_rate>20</update_rate>
      <camera>
        <horizontal_fov>1.02974425868</horizontal_fov>
        <image>
          <format>B8G8R8</format>
          <width>640</width>
          <height>480</height>
        </image>
        <clip>
          <near>0.5</near>
          <far>10.0</far>
        </clip>
      </camera>
      <plugin filename="libgazebo_ros_openni_kinect.so" name="camera_camera_rgb_controller">
        <robotNamespace>turtlebot3/sensor/camera</robotNamespace>
        <imageTopicName>ir/image_raw</imageTopicName>
        <cameraInfoTopicName>ir/camera_info</cameraInfoTopicName>
        <depthImageTopicName>depth/image_raw</depthImageTopicName>
        <depthImageCameraInfoTopicName>depth/camera_info</depthImageCameraInfoTopicName>
        <pointCloudTopicName>depth/points</pointCloudTopicName>
        <frameName>camera_depth_optical_frame</frameName>
      </plugin>
    </sensor>
  </gazebo>
  <transmission name="arm_joint_1_joint_transmission">
    <type>transmission_interface/SimpleTransmission</type>
    <joint name="arm_joint_1">
      <hardwareInterface>hardware_interface/EffortJointInterface</hardwareInterface>
    </joint>
    <actuator name="arm_joint_1_motor">
      <hardwareInterface>hardware_interface/EffortJointInterface</hardwareInterface>
      <mechanicalReduction>1</mechanicalReduction>
    </actuator>
  </transmission>
  <transmission name="arm_joint_2_joint_transmission">
    <type>transmission_interface/SimpleTransmission</type>
    <joint name="arm_joint_2">
      <hardwareInterface>hardware_interface/EffortJointInterface</hardwareInterface>
    </joint>
    <actuator name="arm_joint_2_motor">
      <hardwareInterface>hardware_interface/EffortJointInterface</hardwareInterface>
      <mechanicalReduction>1</mechanicalReduction>
    </actuator>
  </transmission>
  <transmission name="arm_joint_3_joint_transmission">
    <type>transmission_interface/SimpleTransmission</type>
    <joint name="arm_joint_3">
      <hardwareInterface>hardware_interface/EffortJointInterface</hardwareInterface>
    </joint>
    <actuator name="arm_joint_3_motor">
      <hardwareInterface>hardware_interface/EffortJointInterface</hardwareInterface>
      <mechanicalReduction>1</mechanicalReduction>
    </actuator>
  </transmission>
  <transmission name="arm_joint_4_joint_transmission">
    <type>transmission_interface/SimpleTransmission</type>
    <joint name="arm_joint_4">
      <hardwareInterface>hardware_interface/EffortJointInterface</hardwareInterface>
    </joint>
    <actuator name="arm_joint_4_motor">
      <hardwareInterface>hardware_interface/EffortJointInterface</hardwareInterface>
      <mechanicalReduction>1</mechanicalReduction>
    </actuator>
  </transmission>
  <transmission name="gripper_servo_joint_transmission">
    <type>transmission_interface/SimpleTransmission</type>
    <joint name="gripper_servo_joint">
      <hardwareInterface>hardware_interface/EffortJointInterface</hardwareInterface>
    </joint>
    <actuator name="gripper_servo_joint_motor">
      <hardwareInterface>hardware_interface/EffortJointInterface</hardwareInterface>
      <mechanicalReduction>1</mechanicalReduction>
    </actuator>
  </transmission>
  <gazebo>
    <plugin filename="libroboticsgroup_gazebo_mimic_joint_plugin.so" name="mimic_gripper_finger_joint_1">
      <robotNamespace>/gazebo/turtlebot3/joints</robotNamespace>
      <joint>gripper_servo_joint</joint>
      <mimicJoint>gripper_finger_joint_1</mimicJoint>
      <multiplier>0.347826086957</multiplier>
      <offset>0</offset>
      <maxEffort>1</maxEffort>
      <hasPID/>
    </plugin>
  </gazebo>
  <gazebo>
    <plugin filename="libroboticsgroup_gazebo_mimic_joint_plugin.so" name="mimic_gripper_finger_joint_2">
      <robotNamespace>/gazebo/turtlebot3/joints</robotNamespace>
      <joint>gripper_servo_joint</joint>
      <mimicJoint>gripper_finger_joint_2</mimicJoint>
      <multiplier>0.347826086957</multiplier>
      <offset>0</offset>
      <maxEffort>1</maxEffort>
      <hasPID/>
    </plugin>
  </gazebo>
  <gazebo>
    <plugin filename="libgazebo_grasp_fix.so" name="gazebo_grasp_fix">
      <arm>
        <arm_name>manipulator_arm</arm_name>
        <palm_link>gripper_base_link</palm_link>
        <gripper_link>gripper_finger_link_1</gripper_link>
        <gripper_link>gripper_finger_link_2</gripper_link>
      </arm>
      <forces_angle_tolerance>120</forces_angle_tolerance>
      <update_rate>5</update_rate>
      <grip_count_threshold>2</grip_count_threshold>
      <max_grip_count>8</max_grip_count>
      <release_tolerance>0.005</release_tolerance>
      <disable_collisions_on_attach>false</disable_collisions_on_attach>
      <contact_topic>__default_topic__</contact_topic>
    </plugin>
  </gazebo>
  <gazebo reference="arm_link_1">
    <material>Gazebo/DarkGrey</material>
  </gazebo>
  <gazebo reference="arm_link_2">
    <material>Gazebo/DarkGrey</material>
  </gazebo>
  <gazebo reference="arm_link_3">
    <material>Gazebo/DarkGrey</material>
  </gazebo>
  <gazebo reference="arm_link_4">
    <material>Gazebo/DarkGrey</material>
  </gazebo>
  <gazebo reference="gripper_base_link">
    <material>Gazebo/DarkGrey</material>
  </gazebo>
  <gazebo reference="gripper_finger_link_1">
    <material>Gazebo/DarkGrey</material>
  </gazebo>
  <gazebo reference="gripper_finger_link_2">
    <material>Gazebo/DarkGrey</material>
  </gazebo>
  <gazebo reference="gripper_grasp_link">
    <material>Gazebo/Red</material>
  </gazebo>
  <joint name="arm_base" type="fixed">
    <origin rpy="0.0 0.0 0.0" xyz="0.136 0.0 0.0463"/>
    <parent link="base_link"/>
    <child link="arm_link_1"/>
  </joint>
  <link name="arm_link_1">
    <visual>
      <origin rpy="0.0 0.0 3.14159265359" xyz="0 0.0 0.0"/>
      <geometry>
        <mesh filename="package://tuda_turtlebot3_arm_description/meshes/arm/link0.stl" scale="0.001 0.001 0.001"/>
      </geometry>
      <material name="DarkGrey">
        <color rgba="0.3 0.3 0.3 1"/>
      </material>
    </visual>
    <collision>
      <origin rpy="0.0 0.0 3.14159265359" xyz="-0.011 0 0.018"/>
      <geometry>
        <box size="0.05 0.03 0.035"/>
      </geometry>
    </collision>
    <inertial>
      <origin rpy="0.0 0.0 3.14159265359" xyz="-0.0129 0.00024 0.01759"/>
      <mass value="0.082"/>
      <inertia ixx="48.546e-06" ixy="-0.218e-06" ixz="-0.416e-06" iyy="25.118e-06" iyz="17.510e-06" izz="4.077e-06"/>
    </inertial>
  </link>
  <joint name="arm_joint_1" type="revolute">
    <origin rpy="0.0 0.0 3.14159265359" xyz="0.0 0 0.036"/>
    <axis xyz="0.0 0.0 1"/>
    <limit effort="4.1" lower="-3.14059265359" upper="3.14059265359" velocity="4.8171087355"/>
    <parent link="arm_link_1"/>
    <child link="arm_link_2"/>
    <dynamics damping="0.2" friction="0.5"/>
  </joint>
  <link name="arm_link_2">
    <visual>
      <origin rpy="0.0 0.0 0.0" xyz="0 0.0 0.0"/>
      <geometry>
        <mesh filename="package://tuda_turtlebot3_arm_description/meshes/arm/link1.stl" scale="0.001 0.001 0.001"/>
      </geometry>
      <material name="DarkGrey">
        <color rgba="0.3 0.3 0.3 1"/>
      </material>
    </visual>
    <collision>
      <origin rpy="0.0 0.0 0.0" xyz="0.0 0 0.025"/>
      <geometry>
        <box size="0.03 0.04 0.055"/>
      </geometry>
    </collision>
    <inertial>
      <origin rpy="0.0 0.0 0.0" xyz="0.00023 -0.00056 0.026"/>
      <mass value="0.088"/>
      <inertia ixx="13.346e-06" ixy="0.224e-06" ixz="0.323e-06" iyy="7.757e-06" iyz="0.438e-06" izz="14.284e-06"/>
    </inertial>
  </link>
  <joint name="arm_joint_2" type="revolute">
    <origin rpy=" 1.57079632679 0.0 3.14159265359" xyz="0.0 0.0 0.0405"/>
    <axis xyz="0.0 0.0 1"/>
    <limit effort="4.1" lower="-1.74532925199" upper="1.74532925199" velocity="4.8171087355"/>
    <parent link="arm_link_2"/>
    <child link="arm_link_3"/>
    <dynamics damping="0.2" friction="0.5"/>
  </joint>
  <link name="arm_link_3">
    <visual>
      <origin rpy="0.0 0.0 0.0" xyz="0.0 0.0 0.0"/>
      <geometry>
        <mesh filename="package://tuda_turtlebot3_arm_description/meshes/arm/link2.stl" scale="0.001 0.001 0.001"/>
      </geometry>
      <material name="DarkGrey">
        <color rgba="0.3 0.3 0.3 1"/>
      </material>
    </visual>
    <collision>
      <origin rpy="0.0 0.0 0.0" xyz="0 0.078 0.0"/>
      <geometry>
        <box size="0.03 0.11 0.035"/>
      </geometry>
    </collision>
    <collision>
      <origin rpy="0.0 0.0 0.0" xyz="0.012 0.145 0.0"/>
      <geometry>
        <box size="0.05 0.035 0.04"/>
      </geometry>
    </collision>
    <collision>
      <origin rpy="0.0 0.0 0.0" xyz="0.0 0.01 0.02"/>
      <geometry>
        <box size="0.03 0.04 0.0075"/>
      </geometry>
    </collision>
    <collision>
      <origin rpy="0.0 0.0 0.0" xyz="0.0 0.01 -0.02"/>
      <geometry>
        <box size="0.03 0.04 0.0075"/>
      </geometry>
    </collision>
    <inertial>
      <origin rpy="0.0 3.14159265359 0.0" xyz="0.00746 0.12016 0.00036"/>
      <mass value="0.136"/>
      <inertia ixx="267.630e-06" ixy="25.927e-06" ixz="-0.339e-06" iyy="21.769e-06" iyz="1.571e-06" izz="260.554e-06"/>
    </inertial>
  </link>
  <joint name="arm_joint_3" type="revolute">
    <origin rpy="0.0 0.0 -1.57079632679" xyz="0.024 0.148 0.0"/>
    <axis xyz="0.0 0.0 1"/>
    <limit effort="4.1" lower="-3.14159265359" upper="0.436332312999" velocity="4.8171087355"/>
    <parent link="arm_link_3"/>
    <child link="arm_link_4"/>
    <dynamics damping="0.2" friction="0.5"/>
  </joint>
  <link name="arm_link_4">
    <visual>
      <origin rpy="0.0 0.0 0.0" xyz="0.0 0.0 0.0"/>
      <geometry>
        <mesh filename="package://tuda_turtlebot3_arm_description/meshes/arm/link3.stl" scale="0.001 0.001 0.001"/>
      </geometry>
      <material name="DarkGrey">
        <color rgba="0.3 0.3 0.3 1"/>
      </material>
    </visual>
    <collision>
      <origin rpy="0.0 0.0 0.0" xyz="-0.01 0.0 0.02"/>
      <geometry>
        <box size="0.04 0.03 0.0075"/>
      </geometry>
    </collision>
    <collision>
      <origin rpy="0.0 0.0 0.0" xyz="-0.01 0.0 -0.02"/>
      <geometry>
        <box size="0.04 0.03 0.0075"/>
      </geometry>
    </collision>
    <collision>
      <origin rpy="0.0 0.0 0.0" xyz="-0.09 0.0 0.0"/>
      <geometry>
        <box size="0.145 0.04 0.04"/>
      </geometry>
    </collision>
    <inertial>
      <origin rpy="0.0 0.0 0.0" xyz="-0.11166 0.00016 0.00038"/>
      <mass value="0.127"/>
      <inertia ixx="19.832e-06" ixy="-0.793e-06" ixz="-0.724e-06" iyy="215.338e-06" iyz="-0.221e-06" izz="207.743e-06"/>
    </inertial>
  </link>
  <joint name="arm_joint_4" type="revolute">
    <origin rpy="0.0 0.0 0.0" xyz="-0.15 0.0 0.0"/>
    <axis xyz="0.0 0.0 1"/>
    <limit effort="4.1" lower="-1.65806278939" upper="1.65806278939" velocity="4.8171087355"/>
    <parent link="arm_link_4"/>
    <child link="gripper_base_link"/>
    <dynamics damping="0.2" friction="0.5"/>
  </joint>
  <link name="gripper_base_link">
    <visual>
      <origin rpy="0.0 0.0 0.0" xyz="0.0 0.0 0.0"/>
      <geometry>
        <mesh filename="package://tuda_turtlebot3_arm_description/meshes/gripper/gripper_base.stl" scale="0.001 0.001 0.001"/>
      </geometry>
      <material name="DarkGrey">
        <color rgba="0.3 0.3 0.3 1"/>
      </material>
    </visual>
    <collision>
      <origin rpy="0.0 0.0 0.0" xyz="-0.01 0.0 0.02"/>
      <geometry>
        <box size="0.04 0.03 0.0075"/>
      </geometry>
    </collision>
    <collision>
      <origin rpy="0.0 0.0 0.0" xyz="-0.01 0.0 -0.02"/>
      <geometry>
        <box size="0.04 0.03 0.0075"/>
      </geometry>
    </collision>
    <collision>
      <origin rpy="0.0 0.0 0.0" xyz="-0.05 0.0 0.0"/>
      <geometry>
        <box size="0.05 0.05 0.055"/>
      </geometry>
    </collision>
    <collision>
      <origin rpy="0.0 0.0 0.0" xyz="-0.06 0.0325 0.0"/>
      <geometry>
        <box size="0.0685 0.015 0.055"/>
      </geometry>
    </collision>
    <collision>
      <origin rpy="0.0 0.0 0.0" xyz="-0.06 -0.0325 0.0"/>
      <geometry>
        <box size="0.0685 0.015 0.055"/>
      </geometry>
    </collision>
    <collision>
      <origin rpy="1.57079632679 3.14159265359 0.0" xyz="-0.06908 0.035 0.02"/>
      <geometry>
        <cylinder length="0.01" radius="0.026"/>
      </geometry>
    </collision>
    <collision>
      <origin rpy="1.57079632679 3.14159265359 0.0" xyz="-0.06908 -0.035 0.02"/>
      <geometry>
        <cylinder length="0.01" radius="0.026"/>
      </geometry>
    </collision>
    <collision>
      <origin rpy="-1.57079632679 3.14159265359 0.0" xyz="-0.06908 0.035 -0.02"/>
      <geometry>
        <cylinder length="0.01" radius="0.026"/>
      </geometry>
    </collision>
    <collision>
      <origin rpy="-1.57079632679 3.14159265359 0.0" xyz="-0.06908 -0.035 -0.02"/>
      <geometry>
        <cylinder length="0.01" radius="0.026"/>
      </geometry>
    </collision>
    <collision>
      <origin rpy="1.57079632679 3.14159265359 0.0" xyz="-0.05408 0.0405 -0.01912"/>
      <geometry>
        <cylinder length="0.007" radius="0.00205"/>
      </geometry>
    </collision>
    <collision>
      <origin rpy="1.57079632679 3.14159265359 0.0" xyz="-0.05408 0.0405 0.01887"/>
      <geometry>
        <cylinder length="0.007" radius="0.00205"/>
      </geometry>
    </collision>
    <inertial>
      <origin rpy="0.0 0.0 0.0" xyz="-0.04663 -0.00051 -0.00234"/>
      <mass value="0.155"/>
      <inertia ixx="114.015e-06" ixy="17.253e-06" ixz="-1.650e-06" iyy="70.718e-06" iyz="0.750e-06" izz="141.557e-06"/>
    </inertial>
  </link>
  <joint name="gripper_servo_joint" type="revolute">
    <origin rpy="1.57079632679 0 0.0" xyz="-0.04225 0.0 -0.016"/>
    <axis xyz="0.0 0.0 1"/>
    <limit effort="4.1" lower="-1.93" upper="1.62" velocity="4.8171087355"/>
    <parent link="gripper_base_link"/>
    <child link="gripper_servo_link"/>
    <dynamics damping="0" friction="0"/>
  </joint>
  <link name="gripper_servo_link">
    <inertial>
      <origin rpy="0.0 0.0 0.0" xyz="0.0 0.0 0.0"/>
      <mass value="0.001"/>
      <inertia ixx="1.0e-07" ixy="0.0" ixz="0.0" iyy="1.0e-07" iyz="0.0" izz="1.0e-07"/>
    </inertial>
    <collision>
      <origin rpy="0.0 0.0 0.0" xyz="0 0.0 0.0275"/>
      <geometry>
        <cylinder length="0.01" radius="0.01"/>
      </geometry>
    </collision>
  </link>
  <!-- virtual endeffector joint -->
  <joint name="gripper_grasp" type="fixed">
    <origin rpy="0.0 0.0 3.14159265359" xyz="-0.14 0.0 0.0"/>
    <parent link="gripper_base_link"/>
    <child link="gripper_grasp_link"/>
  </joint>
  <link name="gripper_grasp_link">
    <visual>
      <origin rpy="0.0 0.0 0.0" xyz="0.0 0.0 0.0"/>
      <geometry>
        <sphere radius="0.005"/>
      </geometry>
      <material name="red"/>
    </visual>
    <inertial>
      <origin rpy="0.0 0.0 0.0" xyz="0.0 0.0 0.0"/>
      <mass value="0.0001"/>
      <inertia ixx="1.0e-10" ixy="0.0" ixz="0.0" iyy="1.0e-10" iyz="0.0" izz="1.0e-10"/>
    </inertial>
  </link>
  <!-- gripper finger -->
  <joint name="gripper_finger_joint_1" type="continuous">
    <origin rpy="1.57079632679 2.51327412287 0.0" xyz="-0.06908 0.0 0.02"/>
    <axis xyz="0.0 0.0 1"/>
    <limit effort="4.1" lower="-3.14159265359" upper="3.14159265359" velocity="4.8171087355"/>
    <parent link="gripper_base_link"/>
    <child link="gripper_finger_link_1"/>
    <mimic joint="gripper_servo_joint" multiplier="0.347826086957" offset="0"/>
    <dynamics damping="0.2" friction="0.5"/>
  </joint>
  <link name="gripper_finger_link_1">
    <visual>
      <origin rpy="0.0 0.0 0.0" xyz="0.0 0.0 0.0"/>
      <geometry>
        <mesh filename="package://tuda_turtlebot3_arm_description/meshes/gripper/gripper_finger.stl" scale="-0.001 0.001 0.001"/>
      </geometry>
      <material name="DarkGrey">
        <color rgba="0.3 0.3 0.3 1"/>
      </material>
    </visual>
    <collision>
      <origin rpy="0.0 0.0 0.0" xyz="0 0.0 0.025"/>
      <geometry>
        <cylinder length="0.01" radius="0.023"/>
      </geometry>
    </collision>
    <collision>
      <origin rpy="0.0 0.0 0.0" xyz="0 0.0 -0.025"/>
      <geometry>
        <cylinder length="0.01" radius="0.023"/>
      </geometry>
    </collision>
    <collision>
      <origin rpy="0.0 0.0 -1.01229096616" xyz="0.045 -0.055 0.0"/>
      <geometry>
        <box size="0.095 0.005 0.03"/>
      </geometry>
    </collision>
    <collision>
      <origin rpy="0.0 0.0 -0.541052068118" xyz="0.0275 -0.0725 0.0"/>
      <geometry>
        <box size="0.095 0.005 0.03"/>
      </geometry>
    </collision>
    <collision>
      <origin rpy="0.0 0.0 0.785398163397" xyz="0.005 -0.035 0.0"/>
      <geometry>
        <box size="0.05 0.005 0.03"/>
      </geometry>
    </collision>
    <collision>
      <origin rpy="0.0 0.0 0.785398163397" xyz="0.0 -0.025 0.0"/>
      <geometry>
        <box size="0.03 0.03 0.06"/>
      </geometry>
    </collision>
    <inertial>
      <origin rpy="0.0 0.0 1.57079632679" xyz="0.01764 -0.04373 0.0"/>
      <mass value="0.029"/>
      <inertia ixx="0.000025065339" ixy="-0.000009627959" ixz="2.8255e-8" iyy="0.000022245643" iyz="5.37e-10" izz="0.000027220956"/>
    </inertial>
  </link>
  <joint name="gripper_finger_joint_2" type="continuous">
    <origin rpy="-1.57079632679 3.76991118431 0.0" xyz="-0.06908 0.0 -0.02"/>
    <axis xyz="0.0 0.0 1"/>
    <limit effort="4.1" lower="-3.14159265359" upper="3.14159265359" velocity="4.8171087355"/>
    <parent link="gripper_base_link"/>
    <child link="gripper_finger_link_2"/>
    <mimic joint="gripper_servo_joint" multiplier="0.347826086957" offset="0"/>
    <dynamics damping="0.2" friction="0.5"/>
  </joint>
  <link name="gripper_finger_link_2">
    <visual>
      <origin rpy="0.0 0.0 0.0" xyz="0.0 0.0 0.0"/>
      <geometry>
        <mesh filename="package://tuda_turtlebot3_arm_description/meshes/gripper/gripper_finger.stl" scale="-0.001 0.001 0.001"/>
      </geometry>
      <material name="DarkGrey">
        <color rgba="0.3 0.3 0.3 1"/>
      </material>
    </visual>
    <collision>
      <origin rpy="0.0 0.0 0.0" xyz="0 0.0 0.025"/>
      <geometry>
        <cylinder length="0.01" radius="0.023"/>
      </geometry>
    </collision>
    <collision>
      <origin rpy="0.0 0.0 0.0" xyz="0 0.0 -0.025"/>
      <geometry>
        <cylinder length="0.01" radius="0.023"/>
      </geometry>
    </collision>
    <collision>
      <origin rpy="0.0 0.0 -1.01229096616" xyz="0.045 -0.055 0.0"/>
      <geometry>
        <box size="0.095 0.005 0.03"/>
      </geometry>
    </collision>
    <collision>
      <origin rpy="0.0 0.0 -0.541052068118" xyz="0.0275 -0.0725 0.0"/>
      <geometry>
        <box size="0.095 0.005 0.03"/>
      </geometry>
    </collision>
    <collision>
      <origin rpy="0.0 0.0 0.785398163397" xyz="0.005 -0.035 0.0"/>
      <geometry>
        <box size="0.05 0.005 0.03"/>
      </geometry>
    </collision>
    <collision>
      <origin rpy="0.0 0.0 0.785398163397" xyz="0.0 -0.025 0.0"/>
      <geometry>
        <box size="0.03 0.03 0.06"/>
      </geometry>
    </collision>
    <inertial>
      <origin rpy="0.0 0.0 1.57079632679" xyz="0.01764 -0.04373 0.0"/>
      <mass value="0.029"/>
      <inertia ixx="0.000025065339" ixy="-0.000009627959" ixz="2.8255e-8" iyy="0.000022245643" iyz="5.37e-10" izz="0.000027220956"/>
    </inertial>
  </link>
</robot>
